<?xml version="1.0" encoding="utf-8"?>
<!-- This URDF was automatically created by SolidWorks to URDF Exporter! Originally created by Stephen Brawner (brawner@gmail.com) 
     Commit Version: 1.6.0-4-g7f85cfe  Build Version: 1.6.7995.38578
     For more information, please see http://wiki.ros.org/sw_urdf_exporter -->
<robot
  name="hero">
  <link
    name="base_link">
    <inertial>
      <origin
        xyz="0.00022371 -0.0010023 0.13309"
        rpy="0 0 0" />
      <mass
        value="67.399" />
      <inertia
        ixx="2.168"
        ixy="-1.3646E-05"
        ixz="-0.0014004"
        iyy="2.1185"
        iyz="0.0077433"
        izz="3.8624" />
    </inertial>
    <visual>
      <origin
        xyz="0 0 0"
        rpy="0 0 0" />
      <geometry>
        <mesh
          filename="package://hero/meshes/base_link.STL" />
      </geometry>
      <material
        name="base_link">
        <color
          rgba="0.984 0.737 0.020 1" />
      </material>
    </visual>
    <collision>
      <origin
        xyz="0 0 0"
        rpy="0 0 0" />
      <geometry>
        <mesh
          filename="package://hero/meshes/base_link.STL" />
      </geometry>
    </collision>
  </link>
  <link
    name="mount_link">
    <inertial>
      <origin
        xyz="-0.012913 0.14322 -0.0023258"
        rpy="0 0 0" />
      <mass
        value="9.6692" />
      <inertia
        ixx="0.14095"
        ixy="0.013309"
        ixz="-0.0031604"
        iyy="0.11751"
        iyz="0.0009584"
        izz="0.16804" />
    </inertial>
    <visual>
      <origin
        xyz="0 0 0"
        rpy="0 0 0" />
      <geometry>
        <mesh
          filename="package://hero/meshes/mount_link.STL" />
      </geometry>
      <material
        name="mount_link">
        <color
          rgba="0.79216 0.81961 0.93333 1" />
      </material>
    </visual>
    <collision>
      <origin
        xyz="0 0 0"
        rpy="0 0 0" />
      <geometry>
        <mesh
          filename="package://hero/meshes/mount_link.STL" />
      </geometry>
    </collision>
  </link>
  <joint
    name="mount_joint"
    type="continuous">
    <origin
      xyz="0 0 0.2341"
      rpy="1.5708 0 -3.1416" />
    <parent
      link="base_link" />
    <child
      link="mount_link" />
    <axis
      xyz="0 1 0" />
  </joint>
  <link
    name="turret_link">
    <inertial>
      <origin
        xyz="7.1618E-08 0.0031106 0.011239"
        rpy="0 0 0" />
      <mass
        value="3.2413" />
      <inertia
        ixx="0.042655"
        ixy="1.6627E-10"
        ixz="1.7711E-08"
        iyy="0.043453"
        iyz="-0.0018182"
        izz="0.0049322" />
    </inertial>
    <visual>
      <origin
        xyz="0 0 0"
        rpy="0 0 0" />
      <geometry>
        <mesh
          filename="package://hero/meshes/turret_link.STL" />
      </geometry>
      <material
        name="turret_link">
        <color
          rgba="0.79216 0.81961 0.93333 1" />
      </material>
    </visual>
    <collision>
      <origin
        xyz="0 0 0"
        rpy="0 0 0" />
      <geometry>
        <mesh
          filename="package://hero/meshes/turret_link.STL" />
      </geometry>
    </collision>
  </link>
  <joint
    name="turret_joint"
    type="continuous">
    <origin
      xyz="0 0.354 0"
      rpy="0 0 0" />
    <parent
      link="mount_link" />
    <child
      link="turret_link" />
    <axis
      xyz="1 0 0" />
  </joint>
  <link
    name="plates_link">
    <inertial>
      <origin
        xyz="0 0 0"
        rpy="0 0 0" />
      <mass
        value="0" />
      <inertia
        ixx="0"
        ixy="0"
        ixz="0"
        iyy="0"
        iyz="0"
        izz="0" />
    </inertial>
    <visual>
      <origin
        xyz="0 0 0"
        rpy="0 0 0" />
      <geometry>
        <mesh
          filename="package://hero/meshes/plates_link.STL" />
      </geometry>
      <material
        name="plates_link">
        <color
          rgba="0 0 0 1" />
      </material>
    </visual>
    <collision>
      <origin
        xyz="0 0 0"
        rpy="0 0 0" />
      <geometry>
        <mesh
          filename="package://hero/meshes/plates_link.STL" />
      </geometry>
    </collision>
  </link>
  <joint
    name="plates_joint"
    type="fixed">
    <origin
      xyz="0 0 0"
      rpy="0 0 0" />
    <parent
      link="base_link" />
    <child
      link="plates_link" />
    <axis
      xyz="0 0 0" />
  </joint>
  <link
    name="lightbars_link">
    <inertial>
      <origin
        xyz="-2.82E-14 2.1982E-14 0.14331"
        rpy="0 0 0" />
      <mass
        value="0.0051135" />
      <inertia
        ixx="1.1406E-06"
        ixy="-7.3389E-21"
        ixz="6.8259E-19"
        iyy="1.1406E-06"
        iyz="9.6694E-21"
        izz="9.472E-08" />
    </inertial>
    <visual>
      <origin
        xyz="0 0 0"
        rpy="0 0 0" />
      <geometry>
        <mesh
          filename="package://hero/meshes/lightbars_link.STL" />
      </geometry>
      <material
        name="lightbars_link">
        <color
          rgba="0 0 1 1" />
      </material>
    </visual>
    <collision>
      <origin
        xyz="0 0 0"
        rpy="0 0 0" />
      <geometry>
        <mesh
          filename="package://hero/meshes/lightbars_link.STL" />
      </geometry>
    </collision>
  </link>
  <joint
    name="lightbars_joint"
    type="fixed">
    <origin
      xyz="0 0 0"
      rpy="0 0 0" />
    <parent
      link="plates_link" />
    <child
      link="lightbars_link" />
    <axis
      xyz="0 0 0" />
  </joint>
  <link
    name="numbers_link">
    <inertial>
      <origin
        xyz="-9.4036E-14 -8.8818E-16 0.14823"
        rpy="0 0 0" />
      <mass
        value="0.0005916" />
      <inertia
        ixx="4.8435E-07"
        ixy="-4.8266E-22"
        ixz="2.5431E-19"
        iyy="4.8435E-07"
        iyz="6.9748E-21"
        izz="6.0113E-08" />
    </inertial>
    <visual>
      <origin
        xyz="0 0 0"
        rpy="0 0 0" />
      <geometry>
        <mesh
          filename="package://hero/meshes/numbers_link.STL" />
      </geometry>
      <material
        name="numbers_link">
        <color
          rgba="1 1 1 1" />
      </material>
    </visual>
    <collision>
      <origin
        xyz="0 0 0"
        rpy="0 0 0" />
      <geometry>
        <mesh
          filename="package://hero/meshes/numbers_link.STL" />
      </geometry>
    </collision>
  </link>
  <joint
    name="numbers_joint"
    type="fixed">
    <origin
      xyz="0 0 0"
      rpy="0 0 0" />
    <parent
      link="plates_link" />
    <child
      link="numbers_link" />
    <axis
      xyz="0 0 0" />
  </joint>
</robot>